<mujoco model="acrobot">
  <compiler angle="radian"/>

  <option timestep="0.01" integrator="RK4">
    <flag constraint="disable" energy="enable"/>
  </option>

  <visual>
    <quality shadowsize="2048"/>
    <headlight ambient="0.4 0.4 0.4" diffuse="0.8 0.8 0.8" specular="0.1 0.1 0.1"/>
  </visual>

  <default>
    <joint damping="0.05"/>
    <geom type="capsule"/>
  </default>

  <asset>
    <texture type="skybox" name="skybox" builtin="gradient" mark="random" rgb1="0.4 0.6 0.8" rgb2="0 0 0" markrgb="1 1 1" width="800" height="4800"/>
    <texture type="2d" name="grid" builtin="checker" mark="edge" rgb1="0.1 0.2 0.3" rgb2="0.2 0.3 0.4" markrgb="0.2 0.3 0.4" width="300" height="300"/>
    <material name="grid" texture="grid" texuniform="true" reflectance="0.2"/>
    <material name="self" rgba="0.7 0.5 0.3 1"/>
    <material name="self_default" rgba="0.7 0.5 0.3 1"/>
    <material name="self_highlight" rgba="0 0.5 0.3 1"/>
    <material name="effector" rgba="0.7 0.4 0.2 1"/>
    <material name="effector_default" rgba="0.7 0.4 0.2 1"/>
    <material name="effector_highlight" rgba="0 0.5 0.3 1"/>
    <material name="decoration" rgba="0.3 0.5 0.7 1"/>
    <material name="eye" rgba="0 0.2 1 1"/>
    <material name="target" rgba="0.6 0.3 0.3 1"/>
    <material name="target_default" rgba="0.6 0.3 0.3 1"/>
    <material name="target_highlight" rgba="0.6 0.3 0.3 0.4"/>
    <material name="site" rgba="0.5 0.5 0.5 0.3"/>
  </asset>

  <worldbody>
    <geom name="floor" size="3 3 0.2" type="plane" material="grid"/>
    <site name="target" pos="0 0 4" size="0.2" group="3" material="target"/>
    <camera name="fixed" pos="0 -6 2" quat="0.707107 0.707107 0 0"/>
    <camera name="lookat" target="upper_arm" pos="0 -2 3" mode="targetbodycom"/>
    <light name="light" pos="0 0 6" dir="0 0 -1"/>
    <body name="upper_arm" pos="0 0 2">
      <joint name="shoulder" pos="0 0 0" axis="0 1 0"/>
      <geom name="upper_arm_decoration" size="0.051 0.06" quat="0.707107 0.707107 0 0" type="cylinder" mass="0" material="decoration"/>
      <geom name="upper_arm" size="0.05 0.5" pos="0 0 0.5" quat="0 1 0 0" type="capsule" mass="1" material="self"/>
      <body name="lower_arm" pos="0 0 1">
        <joint name="elbow" pos="0 0 0" axis="0 1 0"/>
        <geom name="lower_arm" size="0.049 0.5" pos="0 0 0.5" quat="0 1 0 0" type="capsule" mass="1" material="self"/>
        <site name="tip" pos="0 0 1" size="0.01"/>
      </body>
    </body>
  </worldbody>

  <actuator>
    <general name="elbow" joint="elbow" ctrllimited="true" ctrlrange="-1 1" gear="2 0 0 0 0 0"/>
  </actuator>
</mujoco>
