<mujoco model="humanoid">
  <compiler angle="radian"/>

  <option timestep="0.005"/>

  <visual>
    <quality shadowsize="2048"/>
    <headlight ambient="0.4 0.4 0.4" diffuse="0.8 0.8 0.8" specular="0.1 0.1 0.1"/>
  </visual>

  <statistic extent="2" center="0 0 1"/>

  <default>
    <general ctrllimited="true" ctrlrange="-1 1"/>
    <default class="body">
      <joint solimplimit="0 0.99 0.01" stiffness="1" limited="true" armature="0.01" damping="0.2"/>
      <geom type="capsule" condim="1" friction="0.7" solref="0.015" solimp="0.9 0.99 0.003" material="self"/>
      <site size="0.04 0.005 0.005" group="3"/>
      <default class="big_joint">
        <joint stiffness="10" damping="5"/>
        <default class="big_stiff_joint">
          <joint stiffness="20"/>
        </default>
      </default>
      <default class="force-torque">
        <site size="0.01 0.01 0.02" type="box" rgba="1 0 0 1"/>
      </default>
      <default class="touch">
        <site type="capsule" rgba="0 0 1 0.3"/>
      </default>
    </default>
  </default>

  <asset>
    <texture type="skybox" name="skybox" builtin="gradient" mark="random" rgb1="0.4 0.6 0.8" rgb2="0 0 0" markrgb="1 1 1" width="800" height="4800"/>
    <texture type="2d" name="grid" builtin="checker" mark="edge" rgb1="0.1 0.2 0.3" rgb2="0.2 0.3 0.4" markrgb="0.2 0.3 0.4" width="300" height="300"/>
    <material name="grid" texture="grid" texuniform="true" reflectance="0.2"/>
    <material name="self" rgba="0.7 0.5 0.3 1"/>
    <material name="self_default" rgba="0.7 0.5 0.3 1"/>
    <material name="self_highlight" rgba="0 0.5 0.3 1"/>
    <material name="effector" rgba="0.7 0.4 0.2 1"/>
    <material name="effector_default" rgba="0.7 0.4 0.2 1"/>
    <material name="effector_highlight" rgba="0 0.5 0.3 1"/>
    <material name="decoration" rgba="0.3 0.5 0.7 1"/>
    <material name="eye" rgba="0 0.2 1 1"/>
    <material name="target" rgba="0.6 0.3 0.3 1"/>
    <material name="target_default" rgba="0.6 0.3 0.3 1"/>
    <material name="target_highlight" rgba="0.6 0.3 0.3 0.4"/>
    <material name="site" rgba="0.5 0.5 0.5 0.3"/>
  </asset>

  <worldbody>
    <geom name="floor" size="100 100 0.2" type="plane" material="grid"/>
    <body name="torso" childclass="body" pos="0 0 1.5">
      <joint name="root" type="free" solimplimit="0.9 0.95 0.001" stiffness="0" limited="false" actuatorfrclimited="false" armature="0" damping="0"/>
      <geom name="torso" size="0.07 0.07" quat="0.707107 0.707107 0 0"/>
      <geom name="upper_waist" size="0.06 0.06" pos="-0.01 0 -0.12" quat="0.707107 0.707107 0 0"/>
      <site name="root" class="force-torque" pos="0 0 0"/>
      <site name="torso" class="touch" pos="0 0 -0.05" size="0.075 0.14 0.13" type="box"/>
      <camera name="back" pos="-3 0 1" quat="0.601501 0.371748 -0.371748 -0.601501" mode="trackcom"/>
      <camera name="side" pos="0 -3 1" quat="0.850651 0.525731 0 0" mode="trackcom"/>
      <light name="top" pos="0 0 2" dir="0 0 -1" mode="trackcom"/>
      <body name="head" pos="0 0 0.19">
        <geom name="head" size="0.09" type="sphere"/>
        <site name="head" class="touch" pos="0 0 0" size="0.091" type="sphere"/>
        <camera name="egocentric" pos="0.09 0 0" quat="0.524286 0.474472 -0.474472 -0.524286" fovy="80"/>
      </body>
      <body name="lower_waist" pos="-0.01 0 -0.26" quat="0.999998 0 -0.002 0">
        <joint name="abdomen_z" class="big_stiff_joint" pos="0 0 0.065" axis="0 0 1" range="-0.785398 0.785398"/>
        <joint name="abdomen_y" class="big_joint" pos="0 0 0.065" axis="0 1 0" range="-1.309 0.523599"/>
        <geom name="lower_waist" size="0.06 0.06" quat="0.707107 0.707107 0 0"/>
        <site name="lower_waist" class="touch" pos="0 0 0" quat="0.707107 -0.707107 0 0" size="0.061 0.06"/>
        <body name="pelvis" pos="0 0 -0.165" quat="0.999998 0 -0.002 0">
          <joint name="abdomen_x" class="big_joint" pos="0 0 0.1" axis="1 0 0" range="-0.610865 0.610865"/>
          <geom name="butt" size="0.09 0.07" pos="-0.02 0 0" quat="0.707107 0.707107 0 0"/>
          <site name="butt" class="touch" pos="-0.02 0 0" quat="0.707107 -0.707107 0 0" size="0.091 0.07"/>
          <body name="right_thigh" pos="0 -0.1 -0.04">
            <joint name="right_hip_x" class="big_joint" pos="0 0 0" axis="1 0 0" range="-0.436332 0.0872665"/>
            <joint name="right_hip_z" class="big_joint" pos="0 0 0" axis="0 0 1" range="-1.0472 0.610865"/>
            <joint name="right_hip_y" class="big_stiff_joint" pos="0 0 0" axis="0 1 0" range="-1.91986 0.349066"/>
            <geom name="right_thigh" size="0.06 0.170074" pos="0 0.005 -0.17" quat="0.999892 0.0147011 0 0"/>
            <site name="right_hip" class="force-torque" pos="0 0 0"/>
            <site name="right_thigh" class="touch" pos="0 0.005 -0.17" quat="0.999892 0.0147011 0 0" size="0.061 0.17"/>
            <body name="right_shin" pos="0 0.01 -0.403">
              <joint name="right_knee" pos="0 0 0.02" axis="0 -1 0" range="-2.79253 0.0349066"/>
              <geom name="right_shin" size="0.049 0.15" pos="0 0 -0.15"/>
              <site name="right_knee" class="force-torque" pos="0 0 0.02"/>
              <site name="right_shin" class="touch" pos="0 0 -0.15" size="0.05 0.15"/>
              <body name="right_foot" pos="0 0 -0.39">
                <joint name="right_ankle_y" pos="0 0 0.08" axis="0 1 0" stiffness="6" range="-0.872665 0.872665"/>
                <joint name="right_ankle_x" pos="0 0 0.04" axis="0.894427 0 0.447214" stiffness="3" range="-0.872665 0.872665"/>
                <geom name="right_right_foot" size="0.027 0.105475" pos="0.035 -0.03 0" quat="0.707107 -0.0670402 -0.703922 0"/>
                <geom name="left_right_foot" size="0.027 0.105475" pos="0.035 0.01 0" quat="0.707107 0.0670402 -0.703922 0"/>
                <site name="right_ankle" class="force-torque" pos="0 0 0"/>
                <site name="right_right_foot" class="touch" pos="0.035 -0.03 0" quat="0.707107 0.0670402 0.703922 0" size="0.03 0.11"/>
                <site name="left_right_foot" class="touch" pos="0.035 0.01 0" quat="0.707107 -0.0670402 0.703922 0" size="0.03 0.11"/>
              </body>
            </body>
          </body>
          <body name="left_thigh" pos="0 0.1 -0.04">
            <joint name="left_hip_x" class="big_joint" pos="0 0 0" axis="-1 0 0" range="-0.436332 0.0872665"/>
            <joint name="left_hip_z" class="big_joint" pos="0 0 0" axis="0 0 -1" range="-1.0472 0.610865"/>
            <joint name="left_hip_y" class="big_stiff_joint" pos="0 0 0" axis="0 1 0" range="-2.0944 0.349066"/>
            <geom name="left_thigh" size="0.06 0.170074" pos="0 -0.005 -0.17" quat="0.999892 -0.0147011 0 0"/>
            <site name="left_hip" class="force-torque" pos="0 0 0"/>
            <site name="left_thigh" class="touch" pos="0 -0.005 -0.17" quat="0.999892 -0.0147011 0 0" size="0.061 0.17"/>
            <body name="left_shin" pos="0 -0.01 -0.403">
              <joint name="left_knee" pos="0 0 0.02" axis="0 -1 0" range="-2.79253 0.0349066"/>
              <geom name="left_shin" size="0.049 0.15" pos="0 0 -0.15"/>
              <site name="left_knee" class="force-torque" pos="0 0 0.02"/>
              <site name="left_shin" class="touch" pos="0 0 -0.15" size="0.05 0.15"/>
              <body name="left_foot" pos="0 0 -0.39">
                <joint name="left_ankle_y" pos="0 0 0.08" axis="0 1 0" stiffness="6" range="-0.872665 0.872665"/>
                <joint name="left_ankle_x" pos="0 0 0.04" axis="0.894427 0 0.447214" stiffness="3" range="-0.872665 0.872665"/>
                <geom name="left_left_foot" size="0.027 0.105475" pos="0.035 0.03 0" quat="0.707107 0.0670402 -0.703922 0"/>
                <geom name="right_left_foot" size="0.027 0.105475" pos="0.035 -0.01 0" quat="0.707107 -0.0670402 -0.703922 0"/>
                <site name="left_ankle" class="force-torque" pos="0 0 0"/>
                <site name="right_left_foot" class="touch" pos="0.035 -0.01 0" quat="0.707107 0.0670402 0.703922 0" size="0.03 0.11"/>
                <site name="left_left_foot" class="touch" pos="0.035 0.03 0" quat="0.707107 -0.0670402 0.703922 0" size="0.03 0.11"/>
              </body>
            </body>
          </body>
        </body>
      </body>
      <body name="right_upper_arm" pos="0 -0.17 0.06">
        <joint name="right_shoulder1" pos="0 0 0" axis="0.816497 0.408248 0.408248" range="-1.48353 1.0472"/>
        <joint name="right_shoulder2" pos="0 0 0" axis="0 -0.707107 0.707107" range="-1.48353 1.0472"/>
        <geom name="right_upper_arm" size="0.04 0.138564" pos="0.08 -0.08 -0.08" quat="0.888074 -0.325058 -0.325058 0"/>
        <site name="right_upper_arm" class="touch" pos="0.08 -0.08 -0.08" quat="0.459701 0.627963 0.627963 0" size="0.041 0.14"/>
        <body name="right_lower_arm" pos="0.18 -0.18 -0.18">
          <joint name="right_elbow" pos="0 0 0" axis="0 -0.707107 0.707107" stiffness="0" range="-1.5708 0.872665"/>
          <geom name="right_lower_arm" size="0.031 0.138564" pos="0.09 0.09 0.09" quat="0.459701 0.627963 -0.627963 0"/>
          <site name="right_lower_arm" class="touch" pos="0.09 0.09 0.09" quat="0.888074 -0.325058 0.325058 0" size="0.032 0.14"/>
          <body name="right_hand" pos="0.18 0.18 0.18">
            <geom name="right_hand" size="0.04" type="sphere"/>
            <site name="right_hand" class="touch" pos="0 0 0" size="0.041" type="sphere"/>
          </body>
        </body>
      </body>
      <body name="left_upper_arm" pos="0 0.17 0.06">
        <joint name="left_shoulder1" pos="0 0 0" axis="0.816497 -0.408248 0.408248" range="-1.0472 1.48353"/>
        <joint name="left_shoulder2" pos="0 0 0" axis="0 0.707107 0.707107" range="-1.0472 1.48353"/>
        <geom name="left_upper_arm" size="0.04 0.138564" pos="0.08 0.08 -0.08" quat="0.888074 0.325058 -0.325058 0"/>
        <site name="left_upper_arm" class="touch" pos="0.08 0.08 -0.08" quat="0.459701 -0.627963 0.627963 0" size="0.041 0.14"/>
        <body name="left_lower_arm" pos="0.18 0.18 -0.18">
          <joint name="left_elbow" pos="0 0 0" axis="0 -0.707107 -0.707107" stiffness="0" range="-1.5708 0.872665"/>
          <geom name="left_lower_arm" size="0.031 0.138564" pos="0.09 -0.09 0.09" quat="0.459701 -0.627963 -0.627963 0"/>
          <site name="left_lower_arm" class="touch" pos="0.09 -0.09 0.09" quat="0.888074 0.325058 0.325058 0" size="0.032 0.14"/>
          <body name="left_hand" pos="0.18 -0.18 0.18">
            <geom name="left_hand" size="0.04" type="sphere"/>
            <site name="left_hand" class="touch" pos="0 0 0" size="0.041" type="sphere"/>
          </body>
        </body>
      </body>
    </body>
  </worldbody>

  <actuator>
    <general name="abdomen_y" joint="abdomen_y" gear="40 0 0 0 0 0"/>
    <general name="abdomen_z" joint="abdomen_z" gear="40 0 0 0 0 0"/>
    <general name="abdomen_x" joint="abdomen_x" gear="40 0 0 0 0 0"/>
    <general name="right_hip_x" joint="right_hip_x" gear="40 0 0 0 0 0"/>
    <general name="right_hip_z" joint="right_hip_z" gear="40 0 0 0 0 0"/>
    <general name="right_hip_y" joint="right_hip_y" gear="120 0 0 0 0 0"/>
    <general name="right_knee" joint="right_knee" gear="80 0 0 0 0 0"/>
    <general name="right_ankle_x" joint="right_ankle_x" gear="20 0 0 0 0 0"/>
    <general name="right_ankle_y" joint="right_ankle_y" gear="20 0 0 0 0 0"/>
    <general name="left_hip_x" joint="left_hip_x" gear="40 0 0 0 0 0"/>
    <general name="left_hip_z" joint="left_hip_z" gear="40 0 0 0 0 0"/>
    <general name="left_hip_y" joint="left_hip_y" gear="120 0 0 0 0 0"/>
    <general name="left_knee" joint="left_knee" gear="80 0 0 0 0 0"/>
    <general name="left_ankle_x" joint="left_ankle_x" gear="20 0 0 0 0 0"/>
    <general name="left_ankle_y" joint="left_ankle_y" gear="20 0 0 0 0 0"/>
    <general name="right_shoulder1" joint="right_shoulder1" gear="20 0 0 0 0 0"/>
    <general name="right_shoulder2" joint="right_shoulder2" gear="20 0 0 0 0 0"/>
    <general name="right_elbow" joint="right_elbow" gear="40 0 0 0 0 0"/>
    <general name="left_shoulder1" joint="left_shoulder1" gear="20 0 0 0 0 0"/>
    <general name="left_shoulder2" joint="left_shoulder2" gear="20 0 0 0 0 0"/>
    <general name="left_elbow" joint="left_elbow" gear="40 0 0 0 0 0"/>
  </actuator>

  <sensor>
    <subtreelinvel body="torso" name="torso_subtreelinvel"/>
    <accelerometer site="root" name="torso_accel"/>
    <velocimeter site="root" name="torso_vel"/>
    <gyro site="root" name="torso_gyro"/>
    <force site="left_ankle" name="left_ankle_force"/>
    <force site="right_ankle" name="right_ankle_force"/>
    <force site="left_knee" name="left_knee_force"/>
    <force site="right_knee" name="right_knee_force"/>
    <force site="left_hip" name="left_hip_force"/>
    <force site="right_hip" name="right_hip_force"/>
    <torque site="left_ankle" name="left_ankle_torque"/>
    <torque site="right_ankle" name="right_ankle_torque"/>
    <torque site="left_knee" name="left_knee_torque"/>
    <torque site="right_knee" name="right_knee_torque"/>
    <torque site="left_hip" name="left_hip_torque"/>
    <torque site="right_hip" name="right_hip_torque"/>
    <touch site="torso" name="torso_touch"/>
    <touch site="head" name="head_touch"/>
    <touch site="lower_waist" name="lower_waist_touch"/>
    <touch site="butt" name="butt_touch"/>
    <touch site="right_thigh" name="right_thigh_touch"/>
    <touch site="right_shin" name="right_shin_touch"/>
    <touch site="right_right_foot" name="right_right_foot_touch"/>
    <touch site="left_right_foot" name="left_right_foot_touch"/>
    <touch site="left_thigh" name="left_thigh_touch"/>
    <touch site="left_shin" name="left_shin_touch"/>
    <touch site="right_left_foot" name="right_left_foot_touch"/>
    <touch site="left_left_foot" name="left_left_foot_touch"/>
    <touch site="right_upper_arm" name="right_upper_arm_touch"/>
    <touch site="right_lower_arm" name="right_lower_arm_touch"/>
    <touch site="right_hand" name="right_hand_touch"/>
    <touch site="left_upper_arm" name="left_upper_arm_touch"/>
    <touch site="left_lower_arm" name="left_lower_arm_touch"/>
    <touch site="left_hand" name="left_hand_touch"/>
  </sensor>
</mujoco>
